<?xml version="1.0" ?>
<!-- =================================================================================== -->
<!-- |    This document was autogenerated by xacro from diff_drive_robot.urdf.xacro    | -->
<!-- |    EDITING THIS FILE BY HAND IS NOT RECOMMENDED                                 | -->
<!-- =================================================================================== -->
<robot name="diff_drive">
  <!-- Base Link -->
  <link name="base_link">
    <collision>
      <origin rpy="0 0 0" xyz="0 0 0.45"/>
      <geometry>
        <box size="0.5 0.33 0.7"/>
      </geometry>
    </collision>
    <visual>
      <origin rpy="0 0 0" xyz="0 0 0.45"/>
      <geometry>
        <box size="0.5 0.33 0.7"/>
      </geometry>
      <material name="white">
        <color rgba="1 1 1 1"/>
      </material>
    </visual>
    <inertial>
      <origin rpy="0 0 0" xyz="0 0 0.45"/>
      <mass value="30"/>
      <inertia ixx="0.6" ixy="0.0" ixz="0.0" iyy="0.6" iyz="0.0" izz="0.6"/>
    </inertial>
  </link>
  <gazebo reference="base_link">
    <material>Gazebo/White</material>
  </gazebo>
  <joint name="left_wheel_joint" type="continuous">
    <origin rpy="-1.5707 0 0" xyz="0.125 0.21 0.125"/>
    <!-- <origin xyz="0.554283 0.625029 0.3" rpy="-1.5707 0 0" /> -->
    <parent link="base_link"/>
    <child link="left_wheel"/>
    <axis xyz="0 0 1"/>
    <dynamics damping="0.2"/>
  </joint>
  <transmission name="left_trans" type="SimpleTransmission">
    <type>transmission_interface/SimpleTransmission</type>
    <actuator name="left_motor">
      <!-- ギア比 -->
      <mechanicalReduction>1</mechanicalReduction>
    </actuator>
    <joint name="left_wheel_joint">
      <hardwareInterface>hardware_interface/VelocityJointInterface</hardwareInterface>
    </joint>
  </transmission>
  <!-- ${prefix} wheel Link -->
  <link name="left_wheel">
    <collision>
      <geometry>
        <cylinder length="0.085" radius="0.125"/>
      </geometry>
    </collision>
    <visual>
      <geometry>
        <cylinder length="0.085" radius="0.125"/>
      </geometry>
      <material name="red">
        <color rgba="1 0 0 1"/>
      </material>
    </visual>
    <inertial>
      <mass value="3.0"/>
      <inertia ixx="0.3" ixy="0.0" ixz="0.0" iyy="0.3" iyz="0.0" izz="0.3"/>
    </inertial>
  </link>
  <gazebo reference="left_wheel">
    <material>Gazebo/Red</material>
  </gazebo>
  <joint name="right_wheel_joint" type="continuous">
    <origin rpy="-1.5707 0 0" xyz="0.125 -0.21 0.125"/>
    <!-- <origin xyz="0.554283 0.625029 0.3" rpy="-1.5707 0 0" /> -->
    <parent link="base_link"/>
    <child link="right_wheel"/>
    <axis xyz="0 0 1"/>
    <dynamics damping="0.2"/>
  </joint>
  <transmission name="right_trans" type="SimpleTransmission">
    <type>transmission_interface/SimpleTransmission</type>
    <actuator name="right_motor">
      <!-- ギア比 -->
      <mechanicalReduction>1</mechanicalReduction>
    </actuator>
    <joint name="right_wheel_joint">
      <hardwareInterface>hardware_interface/VelocityJointInterface</hardwareInterface>
    </joint>
  </transmission>
  <!-- ${prefix} wheel Link -->
  <link name="right_wheel">
    <collision>
      <geometry>
        <cylinder length="0.085" radius="0.125"/>
      </geometry>
    </collision>
    <visual>
      <geometry>
        <cylinder length="0.085" radius="0.125"/>
      </geometry>
      <material name="red">
        <color rgba="1 0 0 1"/>
      </material>
    </visual>
    <inertial>
      <mass value="3.0"/>
      <inertia ixx="0.3" ixy="0.0" ixz="0.0" iyy="0.3" iyz="0.0" izz="0.3"/>
    </inertial>
  </link>
  <gazebo reference="right_wheel">
    <material>Gazebo/Red</material>
  </gazebo>
  <joint name="caster_joint" type="fixed">
    <origin rpy="1.57 0 0" xyz="-0.25 0 0.05"/>
    <parent link="base_link"/>
    <child link="caster"/>
  </joint>
  <transmission name="caster_trans" type="SimpleTransmission">
    <type>transmission_interface/SimpleTransmission</type>
    <actuator name="caster_motor">
      <!-- ギア比 -->
      <mechanicalReduction>1</mechanicalReduction>
    </actuator>
    <joint name="caster_joint">
      <hardwareInterface>hardware_interface/VelocityJointInterface</hardwareInterface>
    </joint>
  </transmission>
  <!-- caster frontal wheel Link -->
  <link name="caster">
    <collision>
      <geometry>
        <sphere radius="0.05"/>
      </geometry>
    </collision>
    <visual>
      <geometry>
        <sphere radius="0.05"/>
      </geometry>
      <material name="blue">
        <color rgba="0 0 1 1"/>
      </material>
    </visual>
    <inertial>
      <origin rpy="0 0 0" xyz="-0.957138 -0 0.2"/>
      <mass value="1.1"/>
      <inertia ixx="0.1" ixy="0.0" ixz="0.0" iyy="0.1" iyz="0.0" izz="0.1"/>
    </inertial>
  </link>
  <gazebo reference="caster">
    <material>Gazebo/Blue</material>
    <!-- 摩擦係数はとりあえず0にして引っかからないようにする -->
    <mu1>0.0</mu1>
    <mu2>0.0</mu2>
  </gazebo>
  <!-- add lidar joint -->
  <joint name="lidar_joint" type="fixed">
    <origin rpy="0 0 0" xyz="0.3 0 0.2"/>
    <parent link="base_link"/>
    <child link="lidar_link"/>
    <axis xyz="0.0 0.0 1.0"/>
  </joint>
  <link name="lidar_link">
    <inertial>
      <mass value="0.3"/>
      <inertia ixx="0.01" ixy="0.0" ixz="0" iyy="0.01" iyz="0" izz="0.01"/>
    </inertial>
    <visual>
      <geometry>
        <cylinder length="0.1" radius="0.05"/>
      </geometry>
      <material name="red">
        <color rgba="1 0 0 0.7"/>
      </material>
    </visual>
  </link>
  <gazebo reference="lidar_link">
    <material>Gazebo/Red</material>
    <sensor name="gazebo_lidar" type="ray">
      <always_on>true</always_on>
      <visualize>true</visualize>
      <update_rate>20</update_rate>
      <pose>0 0 0 0 0 0</pose>
      <plugin filename="libgazebo_ros_ray_sensor.so" name="gazebo_lidar">
        <ros>
          <remapping>~/out:=scan</remapping>
        </ros>
        <output_type>sensor_msgs/LaserScan</output_type>
        <frame_name>lidar_link</frame_name>
      </plugin>
      <ray>
        <scan>
          <horizontal>
            <samples>640</samples>
            <resolution>1.000000</resolution>
            <min_angle>-1.396263402</min_angle>
            <max_angle>1.396263402</max_angle>
          </horizontal>
        </scan>
        <range>
          <min>0.1</min>
          <max>15.0</max>
          <resolution>0.01</resolution>
        </range>
        <noise>
          <type>gaussian</type>
          <mean>0.0</mean>
          <stddev>0.01</stddev>
        </noise>
      </ray>
    </sensor>
  </gazebo>
  <!-- add imu object -->
  <joint name="imu_joint" type="fixed">
    <origin rpy="0 0 0" xyz="0 0 0.8"/>
    <parent link="base_link"/>
    <child link="imu_link"/>
    <axis xyz="0 0 1.0"/>
  </joint>
  <link name="imu_link">
    <visual>
      <inertial>
        <mass value="0.03"/>
        <inertia ixx="0.01" ixy="0.0" ixz="0" iyy="0.01" iyz="0" izz="0.01"/>
      </inertial>
      <geometry>
        <box size="0.05 0.05 0.05"/>
      </geometry>
      <material name="green">
        <color rgba="0 1 0 0.7"/>
      </material>
    </visual>
    <collision>
      <geometry>
        <box size="0.05 0.05 0.05"/>
      </geometry>
    </collision>
  </link>
  <gazebo reference="imu_link">
    <material>Gazebo/Blue</material>
    <sensor name="my_imu" type="imu">
      <always_on>true</always_on>
      <!-- Publish at 30 hz -->
      <update_rate>50</update_rate>
      <plugin filename="libgazebo_ros_imu_sensor.so" name="my_imu_plugin">
        <ros>
          <!-- Will publish to /imu/data -->
          <namespace>/imu</namespace>
          <remapping>~/out:=data</remapping>
        </ros>
        <!-- frame_name ommited, will be "my_link" -->
      </plugin>
    </sensor>
  </gazebo>
  <ros2_control name="GazeboSystem" type="system">
    <hardware>
      <plugin>gazebo_ros2_control/GazeboSystem</plugin>
    </hardware>
    <joint name="left_wheel_joint">
      <command_interface name="velocity">
        <param name="min">-1</param>
        <param name="max">1</param>
      </command_interface>
      <state_interface name="position"/>
      <!-- <state_interface name="velocity" /> -->
    </joint>
    <joint name="right_wheel_joint">
      <command_interface name="velocity">
        <param name="min">-1</param>
        <param name="max">1</param>
      </command_interface>
      <state_interface name="position"/>
      <!-- <state_interface name="velocity" /> -->
    </joint>
  </ros2_control>
  <gazebo>
    <!-- Joint state publisher -->
    <plugin filename="libgazebo_ros2_control.so" name="gazebo_ros2_control">
      <robot_param>robot_description</robot_param>
      <robot_param_node>robot_state_publisher</robot_param_node>
      <parameters>/home/tatsuki/colcon_ws/install/ouagv_robot_description/share/ouagv_robot_description/config/diff_drive_controller.yaml</parameters>
    </plugin>
  </gazebo>
</robot>
